<?xml version="1.0"?>
<robot name="humanoid_robot">
  <!-- Base link -->
  <link name="base_link">
    <visual>
      <geometry>
        <box size="0.2 0.1 0.1"/>
      </geometry>
      <material name="blue">
        <color rgba="0 0 1 1"/>
      </material>
    </visual>
    <collision>
      <geometry>
        <box size="0.2 0.1 0.1"/>
      </geometry>
    </collision>
    <inertial>
      <mass value="1"/>
      <inertia ixx="0.01" ixy="0" ixz="0" iyy="0.01" iyz="0" izz="0.01"/>
    </inertial>
  </link>

  <!-- Gazebo plugin for base link -->
  <gazebo reference="base_link">
    <mu1>0.2</mu1>
    <mu2>0.2</mu2>
    <kp>1000000.0</kp>
    <kd>100.0</kd>
  </gazebo>

  <!-- Torso -->
  <link name="torso">
    <visual>
      <geometry>
        <box size="0.15 0.1 0.3"/>
      </geometry>
      <material name="red">
        <color rgba="1 0 0 1"/>
      </material>
    </visual>
    <collision>
      <geometry>
        <box size="0.15 0.1 0.3"/>
      </geometry>
    </collision>
    <inertial>
      <mass value="2"/>
      <inertia ixx="0.02" ixy="0" ixz="0" iyy="0.02" iyz="0" izz="0.02"/>
    </inertial>
  </link>

  <joint name="base_to_torso" type="fixed">
    <parent link="base_link"/>
    <child link="torso"/>
    <origin xyz="0 0 0.2"/>
  </joint>

  <!-- Head -->
  <link name="head">
    <visual>
      <geometry>
        <sphere radius="0.075"/>
      </geometry>
      <material name="white">
        <color rgba="1 1 1 1"/>
      </material>
    </visual>
    <collision>
      <geometry>
        <sphere radius="0.075"/>
      </geometry>
    </collision>
    <inertial>
      <mass value="0.5"/>
      <inertia ixx="0.001" ixy="0" ixz="0" iyy="0.001" iyz="0" izz="0.001"/>
    </inertial>
  </link>

  <!-- Gazebo plugin for head -->
  <gazebo reference="head">
    <mu1>0.2</mu1>
    <mu2>0.2</mu2>
    <kp>1000000.0</kp>
    <kd>100.0</kd>
  </gazebo>

  <joint name="torso_to_head" type="fixed">
    <parent link="torso"/>
    <child link="head"/>
    <origin xyz="0 0 0.25"/>
  </joint>

  <!-- Left Arm -->
  <link name="left_upper_arm">
    <visual>
      <geometry>
        <cylinder length="0.2" radius="0.025"/>
      </geometry>
      <material name="green">
        <color rgba="0 1 0 1"/>
      </material>
    </visual>
    <collision>
      <geometry>
        <cylinder length="0.2" radius="0.025"/>
      </geometry>
    </collision>
    <inertial>
      <mass value="0.5"/>
      <inertia ixx="0.001" ixy="0" ixz="0" iyy="0.001" iyz="0" izz="0.001"/>
    </inertial>
  </link>

  <joint name="left_shoulder_pitch" type="revolute">
    <parent link="torso"/>
    <child link="left_upper_arm"/>
    <origin xyz="0.1 0 0.1"/>
    <axis xyz="0 1 0"/>
    <limit lower="-1.57" upper="1.57" effort="100" velocity="1"/>
  </joint>

  <link name="left_lower_arm">
    <visual>
      <geometry>
        <cylinder length="0.2" radius="0.025"/>
      </geometry>
      <material name="green">
        <color rgba="0 1 0 1"/>
      </material>
    </visual>
    <collision>
      <geometry>
        <cylinder length="0.2" radius="0.025"/>
      </geometry>
    </collision>
    <inertial>
      <mass value="0.3"/>
      <inertia ixx="0.001" ixy="0" ixz="0" iyy="0.001" iyz="0" izz="0.001"/>
    </inertial>
  </link>

  <joint name="left_elbow" type="revolute">
    <parent link="left_upper_arm"/>
    <child link="left_lower_arm"/>
    <origin xyz="0 0 -0.2"/>
    <axis xyz="0 1 0"/>
    <limit lower="0" upper="1.57" effort="100" velocity="1"/>
  </joint>

  <!-- Right Arm -->
  <link name="right_upper_arm">
    <visual>
      <geometry>
        <cylinder length="0.2" radius="0.025"/>
      </geometry>
      <material name="green">
        <color rgba="0 1 0 1"/>
      </material>
    </visual>
    <collision>
      <geometry>
        <cylinder length="0.2" radius="0.025"/>
      </geometry>
    </collision>
    <inertial>
      <mass value="0.5"/>
      <inertia ixx="0.001" ixy="0" ixz="0" iyy="0.001" iyz="0" izz="0.001"/>
    </inertial>
  </link>

  <joint name="right_shoulder_pitch" type="revolute">
    <parent link="torso"/>
    <child link="right_upper_arm"/>
    <origin xyz="-0.1 0 0.1"/>
    <axis xyz="0 1 0"/>
    <limit lower="-1.57" upper="1.57" effort="100" velocity="1"/>
  </joint>

  <link name="right_lower_arm">
    <visual>
      <geometry>
        <cylinder length="0.2" radius="0.025"/>
      </geometry>
      <material name="green">
        <color rgba="0 1 0 1"/>
      </material>
    </visual>
    <collision>
      <geometry>
        <cylinder length="0.2" radius="0.025"/>
      </geometry>
    </collision>
    <inertial>
      <mass value="0.3"/>
      <inertia ixx="0.001" ixy="0" ixz="0" iyy="0.001" iyz="0" izz="0.001"/>
    </inertial>
  </link>

  <joint name="right_elbow" type="revolute">
    <parent link="right_upper_arm"/>
    <child link="right_lower_arm"/>
    <origin xyz="0 0 -0.2"/>
    <axis xyz="0 1 0"/>
    <limit lower="0" upper="1.57" effort="100" velocity="1"/>
  </joint>

  <!-- Left Leg -->
  <link name="left_upper_leg">
    <visual>
      <geometry>
        <cylinder length="0.25" radius="0.03"/>
      </geometry>
      <material name="yellow">
        <color rgba="1 1 0 1"/>
      </material>
    </visual>
    <collision>
      <geometry>
        <cylinder length="0.25" radius="0.03"/>
      </geometry>
    </collision>
    <inertial>
      <mass value="0.8"/>
      <inertia ixx="0.002" ixy="0" ixz="0" iyy="0.002" iyz="0" izz="0.002"/>
    </inertial>
  </link>

  <joint name="left_hip_pitch" type="revolute">
    <parent link="base_link"/>
    <child link="left_upper_leg"/>
    <origin xyz="0.05 0 -0.05"/>
    <axis xyz="0 1 0"/>
    <limit lower="-0.785" upper="0.785" effort="100" velocity="1"/>
  </joint>

  <link name="left_lower_leg">
    <visual>
      <geometry>
        <cylinder length="0.25" radius="0.03"/>
      </geometry>
      <material name="yellow">
        <color rgba="1 1 0 1"/>
      </material>
    </visual>
    <collision>
      <geometry>
        <cylinder length="0.25" radius="0.03"/>
      </geometry>
    </collision>
    <inertial>
      <mass value="0.6"/>
      <inertia ixx="0.002" ixy="0" ixz="0" iyy="0.002" iyz="0" izz="0.002"/>
    </inertial>
  </link>

  <joint name="left_knee" type="revolute">
    <parent link="left_upper_leg"/>
    <child link="left_lower_leg"/>
    <origin xyz="0 0 -0.25"/>
    <axis xyz="0 1 0"/>
    <limit lower="0" upper="1.57" effort="100" velocity="1"/>
  </joint>

  <!-- Right Leg -->
  <link name="right_upper_leg">
    <visual>
      <geometry>
        <cylinder length="0.25" radius="0.03"/>
      </geometry>
      <material name="yellow">
        <color rgba="1 1 0 1"/>
      </material>
    </visual>
    <collision>
      <geometry>
        <cylinder length="0.25" radius="0.03"/>
      </geometry>
    </collision>
    <inertial>
      <mass value="0.8"/>
      <inertia ixx="0.002" ixy="0" ixz="0" iyy="0.002" iyz="0" izz="0.002"/>
    </inertial>
  </link>

  <joint name="right_hip_pitch" type="revolute">
    <parent link="base_link"/>
    <child link="right_upper_leg"/>
    <origin xyz="-0.05 0 -0.05"/>
    <axis xyz="0 1 0"/>
    <limit lower="-0.785" upper="0.785" effort="100" velocity="1"/>
  </joint>

  <link name="right_lower_leg">
    <visual>
      <geometry>
        <cylinder length="0.25" radius="0.03"/>
      </geometry>
      <material name="yellow">
        <color rgba="1 1 0 1"/>
      </material>
    </visual>
    <collision>
      <geometry>
        <cylinder length="0.25" radius="0.03"/>
      </geometry>
    </collision>
    <inertial>
      <mass value="0.6"/>
      <inertia ixx="0.002" ixy="0" ixz="0" iyy="0.002" iyz="0" izz="0.002"/>
    </inertial>
  </link>

  <joint name="right_knee" type="revolute">
    <parent link="right_upper_leg"/>
    <child link="right_lower_leg"/>
    <origin xyz="0 0 -0.25"/>
    <axis xyz="0 1 0"/>
    <limit lower="0" upper="1.57" effort="100" velocity="1"/>
  </joint>

  <!-- Joint transmission for control -->
  <transmission name="left_shoulder_pitch_trans">
    <type>transmission_interface/SimpleTransmission</type>
    <joint name="left_shoulder_pitch">
      <hardwareInterface>hardware_interface/EffortJointInterface</hardwareInterface>
    </joint>
    <actuator name="left_shoulder_pitch_motor">
      <hardwareInterface>hardware_interface/EffortJointInterface</hardwareInterface>
      <mechanicalReduction>1</mechanicalReduction>
    </actuator>
  </transmission>

  <transmission name="left_elbow_trans">
    <type>transmission_interface/SimpleTransmission</type>
    <joint name="left_elbow">
      <hardwareInterface>hardware_interface/EffortJointInterface</hardwareInterface>
    </joint>
    <actuator name="left_elbow_motor">
      <hardwareInterface>hardware_interface/EffortJointInterface</hardwareInterface>
      <mechanicalReduction>1</mechanicalReduction>
    </actuator>
  </transmission>

  <transmission name="right_shoulder_pitch_trans">
    <type>transmission_interface/SimpleTransmission</type>
    <joint name="right_shoulder_pitch">
      <hardwareInterface>hardware_interface/EffortJointInterface</hardwareInterface>
    </joint>
    <actuator name="right_shoulder_pitch_motor">
      <hardwareInterface>hardware_interface/EffortJointInterface</hardwareInterface>
      <mechanicalReduction>1</mechanicalReduction>
    </actuator>
  </transmission>

  <transmission name="right_elbow_trans">
    <type>transmission_interface/SimpleTransmission</type>
    <joint name="right_elbow">
      <hardwareInterface>hardware_interface/EffortJointInterface</hardwareInterface>
    </joint>
    <actuator name="right_elbow_motor">
      <hardwareInterface>hardware_interface/EffortJointInterface</hardwareInterface>
      <mechanicalReduction>1</mechanicalReduction>
    </actuator>
  </transmission>

  <transmission name="left_hip_pitch_trans">
    <type>transmission_interface/SimpleTransmission</type>
    <joint name="left_hip_pitch">
      <hardwareInterface>hardware_interface/EffortJointInterface</hardwareInterface>
    </joint>
    <actuator name="left_hip_pitch_motor">
      <hardwareInterface>hardware_interface/EffortJointInterface</hardwareInterface>
      <mechanicalReduction>1</mechanicalReduction>
    </actuator>
  </transmission>

  <transmission name="left_knee_trans">
    <type>transmission_interface/SimpleTransmission</type>
    <joint name="left_knee">
      <hardwareInterface>hardware_interface/EffortJointInterface</hardwareInterface>
    </joint>
    <actuator name="left_knee_motor">
      <hardwareInterface>hardware_interface/EffortJointInterface</hardwareInterface>
      <mechanicalReduction>1</mechanicalReduction>
    </actuator>
  </transmission>

  <transmission name="right_hip_pitch_trans">
    <type>transmission_interface/SimpleTransmission</type>
    <joint name="right_hip_pitch">
      <hardwareInterface>hardware_interface/EffortJointInterface</hardwareInterface>
    </joint>
    <actuator name="right_hip_pitch_motor">
      <hardwareInterface>hardware_interface/EffortJointInterface</hardwareInterface>
      <mechanicalReduction>1</mechanicalReduction>
    </actuator>
  </transmission>

  <transmission name="right_knee_trans">
    <type>transmission_interface/SimpleTransmission</type>
    <joint name="right_knee">
      <hardwareInterface>hardware_interface/EffortJointInterface</hardwareInterface>
    </joint>
    <actuator name="right_knee_motor">
      <hardwareInterface>hardware_interface/EffortJointInterface</hardwareInterface>
      <mechanicalReduction>1</mechanicalReduction>
    </actuator>
  </transmission>

  <!-- Gazebo plugins for sensors and physics -->
  <gazebo reference="head">
    <!-- Depth camera sensor -->
    <sensor name="depth_camera" type="depth">
      <always_on>true</always_on>
      <update_rate>30</update_rate>
      <camera name="head_depth_camera">
        <horizontal_fov>1.047</horizontal_fov>
        <image>
          <width>640</width>
          <height>480</height>
          <format>R8G8B8</format>
        </image>
        <clip>
          <near>0.1</near>
          <far>10</far>
        </clip>
      </camera>
      <plugin name="camera_controller" filename="libgazebo_ros_camera.so">
        <frame_name>head_depth_camera_frame</frame_name>
        <min_depth>0.1</min_depth>
        <max_depth>10.0</max_depth>
      </plugin>
    </sensor>
  </gazebo>

  <gazebo reference="torso">
    <!-- IMU sensor -->
    <sensor name="imu_sensor" type="imu">
      <always_on>true</always_on>
      <update_rate>100</update_rate>
      <plugin name="imu_plugin" filename="libgazebo_ros_imu.so">
        <frame_name>torso_imu_frame</frame_name>
        <topic>sensor_data/imu</topic>
        <serviceName>/imu_service</serviceName>
      </plugin>
    </sensor>
  </gazebo>

  <!-- LiDAR sensor on torso -->
  <gazebo reference="torso">
    <sensor name="laser_sensor" type="ray">
      <pose>0.05 0 0.1 0 0 0</pose>
      <visualize>false</visualize>
      <update_rate>10</update_rate>
      <ray>
        <scan>
          <horizontal>
            <samples>360</samples>
            <resolution>1</resolution>
            <min_angle>-3.14159</min_angle>
            <max_angle>3.14159</max_angle>
          </horizontal>
        </scan>
        <range>
          <min>0.1</min>
          <max>10.0</max>
          <resolution>0.01</resolution>
        </range>
      </ray>
      <plugin name="laser_plugin" filename="libgazebo_ros_laser.so">
        <frame_name>laser_frame</frame_name>
        <topic>sensor_data/laser_scan</topic>
      </plugin>
    </sensor>
  </gazebo>

  <!-- Gazebo control plugin -->
  <gazebo>
    <plugin name="gazebo_ros_control" filename="libgazebo_ros_control.so">
      <robotNamespace>/humanoid_robot</robotNamespace>
    </plugin>
  </gazebo>
</robot>